<?xml version="1.0" ?>
<robot name="TBot">

	<!-- * * * Link Definitions * * * -->
	<mujoco>
        <compiler  
        balanceinertia="true" 
        discardvisual="false" />
	</mujoco>
	
	

  	<link name="torso_link">
		<visual>
			<origin xyz="0 0 0.2" rpy="0 0 0"/>
			<geometry>
				<box size="0.3 0.3 0.4"/>
			</geometry>
		    <material name="Yellow2">
				<color rgba="0.8 0.8 0 1.0"/>
			</material>
		</visual>
		<collision>
			<geometry>
				<box size="0.3 0.3 0.4"/>
			</geometry>
		</collision>
		<inertial>
			<mass value="15.028392" /> 
			<inertia ixx="0.375905" ixy="0.344193" ixz="0.098732" iyy="-8.8e-05"  iyz="0.0085" izz="6.6e-05" /> 
		</inertial>
	</link>
	
	<link name="left_shoulder_link">
		<visual>
			<origin xyz="0 0 0" rpy="0 0 0"/>
			<geometry>
				<box size="0.025 0.015 0.05"/>
			</geometry>
	     	<material name="Green1">
				<color rgba="0 1 0 1.0"/>
			</material>
		</visual>
		<collision>
			<geometry>
				<box size="0.025 0.015 0.05"/>
			</geometry>
		</collision>
		<inertial>
			<mass value="0.535396" /> 
			<inertia ixx="0.000704" ixy="0.00075" ixz="0.000298" iyy="1.4e-05"  iyz="1.2e-05" izz="3.5e-05" /> 
		</inertial>
	</link>
	
	<link name="right_shoulder_link">
		<visual>
			<origin xyz="0 0 0" rpy="0 0 0"/>
			<geometry>
				<box size="0.025 0.015 0.05"/>
			</geometry>
	     	<material name="Green1">
				<color rgba="0 1 0 1.0"/>
			</material>
		</visual>
		<collision>
			<geometry>
				<box size="0.025 0.015 0.05"/>
			</geometry>
		</collision>
		<inertial>
			<mass value="0.535396" /> 
			<inertia ixx="0.000704" ixy="0.00075" ixz="0.000298" iyy="1.4e-05"  iyz="1.2e-05" izz="3.5e-05" /> 
		</inertial>
	</link>
	
	<link name="left_shoulder_forward_link">
		<visual>
			<origin xyz="0 0 0" rpy="0 0 0"/>
			<geometry>
				<box size="0.03 0.05 0.03"/>
			</geometry>
	     	<material name="Blue1">
				<color rgba="0 0 0.9 1.0"/>
			</material>
		</visual>
		<collision>
			<geometry>
				<box size="0.03 0.05 0.03"/>
			</geometry>
		</collision>
		<inertial>
			<mass value="1.440357" /> 
			<inertia ixx="0.006761" ixy="0.002087" ixz="0.005778" iyy="-6e-06"  iyz="-3e-06" izz="-0.002046" /> 
		</inertial>
	</link>
		
	<link name="right_shoulder_forward_link">
		<visual>
			<origin xyz="0 0 0" rpy="0 0 0"/>
			<geometry>
				<box size="0.03 0.05 0.03"/>
			</geometry>
	     	<material name="Blue1">
				<color rgba="0 0 0.9 1.0"/>
			</material>
		</visual>
		<collision>
			<geometry>
				<box size="0.03 0.05 0.03"/>
			</geometry>
		</collision>
		<inertial>
			<mass value="1.440357" /> 
			<inertia ixx="0.006761" ixy="0.002087" ixz="0.005778" iyy="-6e-06"  iyz="-3e-06" izz="-0.002046" /> 
		</inertial>
	</link>
	
	<link name="left_shoulder_up_link">
		<visual>
			<origin xyz="0 0 0" rpy="1.57 0 0"/>
			<geometry>
				<box size="0.03 0.05 0.03"/>
			</geometry>
	     	<material name="Blue2">
				<color rgba="0 0 0.7 1.0"/>
			</material>
		</visual>
		<collision>
			<geometry>
				<box size="0.03 0.05 0.03"/>
			</geometry>
		</collision>
	</link>
	
	<link name="right_shoulder_up_link">
		<visual>
			<origin xyz="0 0 0" rpy="1.57 0 0"/>
			<geometry>
				<box size="0.03 0.05 0.03"/>
			</geometry>
	     	<material name="Blue2">
				<color rgba="0 0 0.7 1.0"/>
			</material>
		</visual>
		<collision>
			<geometry>
				<box size="0.03 0.05 0.03"/>
			</geometry>
		</collision>
	</link>
	
	<link name="left_upper_arm_link">
		<visual>
			<origin xyz="0 0 0" rpy="0 0 0"/>
			<geometry>
				<cylinder radius="0.0075" length="0.05"/>
			</geometry>
	     	<material name="Grey1">
				<color rgba="0.9 0.9 0.9 1.0"/>
			</material>
		</visual>
		<collision>
			<geometry>
				<cylinder radius="0.0075" length="0.05"/>
			</geometry>
		</collision>
		<inertial>
			<mass value="1.065387" /> 
			<inertia ixx="0.006967" ixy="0.007003" ixz="0.000673" iyy="-1e-06"  iyz="-1e-06" izz="-1.5e-05" /> 
		</inertial>
	</link>
	
	<link name="right_upper_arm_link">
		<visual>
			<origin xyz="0 0 0" rpy="0 0 0"/>
			<geometry>
				<cylinder radius="0.0075" length="0.05"/>
			</geometry>
	     	<material name="Grey1">
				<color rgba="0.9 0.9 0.9 1.0"/>
			</material>
		</visual>
		<collision>
			<geometry>
				<cylinder radius="0.0075" length="0.05"/>
			</geometry>
		</collision>
		<inertial>
			<mass value="1.065387" /> 
			<inertia ixx="0.006967" ixy="0.007003" ixz="0.000673" iyy="-1e-06"  iyz="-1e-06" izz="-1.5e-05" /> 
		</inertial>	
	</link>
	
	<link name="left_elbow_link">
		<visual>
			<origin xyz="0 0 0" rpy="0 0 1.57"/>
			<geometry>
				<box size="0.035 0.035 0.05"/>
			</geometry>
	     	<material name="Blue2">
				<color rgba="0 0 0.7 1.0"/>
			</material>
		</visual>
		<collision>
			<geometry>
				<box size="0.035 0.035 0.05"/>
			</geometry>
		</collision>
	</link>
	
	<link name="right_elbow_link">
		<visual>
			<origin xyz="0 0 0" rpy="0 0 1.57"/>
			<geometry>
				<box size="0.035 0.035 0.05"/>
			</geometry>
	     	<material name="Blue2">
				<color rgba="0 0 0.7 1.0"/>
			</material>
		</visual>
		<collision>
			<geometry>
				<box size="0.035 0.035 0.05"/>
			</geometry>
		</collision>
	</link>
	
	<link name="left_lower_arm_link">
		<visual>
			<origin xyz="0 0 0" rpy="0 0 0"/>
			<geometry>
				<cylinder radius="0.0075" length="0.11"/>
			</geometry>
	     	<material name="Grey1">
				<color rgba="0.9 0.9 0.9 1.0"/>
			</material>
		</visual>
		<collision>
			<geometry>
				<cylinder radius="0.0075" length="0.11"/>
			</geometry>
		</collision>
		<inertial>
			<mass value="0.550582" /> 
			<inertia ixx="0.000476" ixy="0.009564" ixz="0.009437" iyy="-2.9e-05"  iyz="0.001403" izz="9e-06" /> 
		</inertial>
	</link>
	
	<link name="right_lower_arm_link">
		<visual>
			<origin xyz="0 0 0" rpy="0 0 0"/>
			<geometry>
				<cylinder radius="0.0075" length="0.11"/>
			</geometry>
	     	<material name="Grey1">
				<color rgba="0.9 0.9 0.9 1.0"/>
			</material>
		</visual>
		<collision>
			<geometry>
				<cylinder radius="0.0075" length="0.11"/>
			</geometry>
		</collision>
		<inertial>
			<mass value="0.550582" /> 
			<inertia ixx="0.000476" ixy="0.009564" ixz="0.009437" iyy="-2.9e-05"  iyz="0.001403" izz="9e-06" /> 
		</inertial>
	</link>
	
	
	<!-- * * * Joint Definitions * * * -->
	
 	<joint name="left_shoulder_joint" type="fixed">
    		<parent link="torso_link"/>
    		<child link="left_shoulder_link"/>
    		<origin xyz="0 0.155 0.365" rpy="0 0 0"/>
	</joint>
	
 	<joint name="right_shoulder_joint" type="fixed">
	    	<parent link="torso_link"/>
	    	<child link="right_shoulder_link"/>
	    	<origin xyz="0 -0.155 0.365" rpy="0 0 0"/>
	</joint>
	
 	<joint name="left_shoulder_forward_joint" type="revolute">
	    	<parent link="left_shoulder_link"/>
	    	<child link="left_shoulder_forward_link"/>
	    	<origin xyz="0 0.025 0" rpy="0 0 0"/>
	       	<limit lower="-1.57" upper="1.57" effort="10" velocity="3"/>
		<axis xyz="1 0 0"/>
	</joint>
	
 	<joint name="right_shoulder_forward_joint" type="revolute">
	    	<parent link="right_shoulder_link"/>
	    	<child link="right_shoulder_forward_link"/>
	    	<origin xyz="0 -0.025 0" rpy="0 0 0"/>
	       	<limit lower="-1.57" upper="1.57" effort="10" velocity="3"/>
		<axis xyz="1 0 0"/>
	</joint>
	
 	<joint name="left_shoulder_up_joint" type="revolute">
	    	<parent link="left_shoulder_forward_link"/>
	    	<child link="left_shoulder_up_link"/>
	    	<origin xyz="0 0.04 -0.01" rpy="0 -0.707 0"/>
	       	<limit lower="-1.57" upper="1.57" effort="10" velocity="3"/>
		<axis xyz="0 1 0"/>
	</joint>
	
 	<joint name="right_shoulder_up_joint" type="revolute">
	    	<parent link="right_shoulder_forward_link"/>
	    	<child link="right_shoulder_up_link"/>
	    	<origin xyz="0 -0.04 -0.01" rpy="0 -0.707 0"/>
	       	<limit lower="-1.57" upper="1.57" effort="10" velocity="3"/>
		<axis xyz="0 1 0"/>
	</joint>
	
 	<joint name="left_upper_arm_joint" type="fixed">
	    	<parent link="left_shoulder_up_link"/>
	    	<child link="left_upper_arm_link"/>
	    	<origin xyz="0 0 -0.05" rpy="0 0 0"/>
	</joint>
	
 	<joint name="right_upper_arm_joint" type="fixed">
	    	<parent link="right_shoulder_up_link"/>
	    	<child link="right_upper_arm_link"/>
	    	<origin xyz="0 0 -0.05" rpy="0 0 0"/>
	</joint>
	
 	<joint name="left_elbow_joint" type="revolute">
	    	<parent link="left_upper_arm_link"/>
	    	<child link="left_elbow_link"/>
	    	<origin xyz="-0.005 0 -0.05" rpy="0 0 0"/>
	       	<limit lower="-3.146" upper="3.146" effort="10" velocity="3"/>
		<axis xyz="0 1 0"/>
	</joint>
	
 	<joint name="right_elbow_joint" type="revolute">
	    	<parent link="right_upper_arm_link"/>
	    	<child link="right_elbow_link"/>
	    	<origin xyz="-0.005 0 -0.05" rpy="0 0 0"/>
	       	<limit lower="-3.146" upper="3.146" effort="10" velocity="3"/>
		<axis xyz="0 1 0"/>
	</joint>
	
 	<joint name="left_lower_arm_joint" type="fixed">
	    	<parent link="left_elbow_link"/>
	    	<child link="left_lower_arm_link"/>
	    	<origin xyz="0 0 -0.08" rpy="0 0 0"/>
	</joint>
	
 	<joint name="right_lower_arm_joint" type="fixed">
	    	<parent link="right_elbow_link"/>
	    	<child link="right_lower_arm_link"/>
	    	<origin xyz="0 0 -0.08" rpy="0 0 0"/>
	</joint>
	 
</robot>
